Workbook

Sheet Сводный отчет - 2026-05-20T1705
A1: Учредитель | B1: ID ИАС | C1: Наименование организации | D1: ОГРН | E1: Тип организации | F1: Федеральный округ | G1: Регион | H1: Город | I1: Адрес | J1: График работы прямого номера телефона, | K1: Прямой номер телефона приемной комиссии для переадресации звонков, полученных от поступающих на номер Единого контактного центра, | L1: Адрес электронной почты приемной комиссии для принятия тикетов от Единого контактного центра , | M1: часовой пояс
A2: Федеральная служба по надзору в сфере защиты прав потребителей и благополучия человека (Роспотребнадзор) | B2: 7594 | C2: "Ростовский-на-Дону ордена Трудового Красного Знамени научно-исследовательский противочумный институт" Федеральной службы по надзору в сфере защиты прав потребителей и благополучия человека | D2: 1026103278959 | E2: Научные учреждения | F2: Южный ФО | G2: Ростовская область | H2: Ростов-на-Дону | I2: 344002, Ростов-на-Дону, Максима Горького, 117 | J2: Понедельник-пятница: 9:00-16:00, перерыв 12:00-13:00, суббота и воскресенье: выходной | K2: 8(863)285-40-65, доб.1517 | L2: plague@aaanet.ru | M2: =VLOOKUP(G2,справочник!$B$1:$C$94,2,0) -> МСК
A3: Министерство Российской Федерации по делам гражданской обороны, чрезвычайным ситуациям и ликвидации последствий стихийных бедствий (МЧС России) | B3: 580 | C3: Сибирская пожарно-спасательная академия Государственной противопожарной службы Министерства Российской Федерации по делам гражданской обороны, чрезвычайным ситуациям и ликвидации последствий стихийных бедствий | D3: 1157847144542 | E3: Высшее образование | F3: Сибирский ФО | G3: Красноярский край | H3: г Железногорск (Красноярский край | I3: 662972, г Железногорск (Красноярский край, Северная, 1 | J3: понедельник- пятница: 8:30-16:30 суббота и воскресенье: выходной | K3: 83919735425 | L3: sib_umo@mail.ru | M3: =VLOOKUP(G3,справочник!$B$1:$C$94,2,0) -> МСК+4
A4: Негосударственная или частная организация | B4: 7778 | C4: "КОНТУР УНИВЕРСИТЕТ" | D4: 1256600034349 | E4: Высшее образование | F4: Уральский ФО | G4: Свердловская область | H4: Екатеринбург | I4: 620014, Екатеринбург, Проспект Ленина, 20а | J4: понедельник-пятница: 09:00 - 17:00 суббота и воскресенье: выходной | K4: +7 (343) 211-32-29 | L4: priem@konturuniversity.ru | M4: =VLOOKUP(G4,справочник!$B$1:$C$94,2,0) -> МСК+2
A5: Федеральное агентство по недропользованию (Роснедра) | B5: 7616 | C5: «ВСЕРОССИЙСКИЙ ГОСУДАРСТВЕННЫЙ ГЕОЛОГИЧЕСКИЙ НЕФТЯНОЙ ИНСТИТУТ» | D5: 1167746108672 | E5: Научные учреждения | F5: Центральный ФО | G5: г.Москва | H5: г.Москва | I5: 105118, г.Москва, Шоссе Энтузиастов, 36 | J5: Понедельник, среда, четверг с 10.00 до 17.00, суббота и воскресенье: выходной | K5: +7 (499) 781-68-63 доб. 3402 | L5: aspirantura@vnigni.ru | M5: =VLOOKUP(G5,справочник!$B$1:$C$94,2,0) -> МСК
A6: Курчатовский институт | B6: 7591 | C6: «Институт физики высоких энергий имени А.А. Логунова Национального исследовательского центра «Курчатовский институт» | D6: 1125043001357 | E6: Научные учреждения | F6: Центральный ФО | G6: Московская область | H6: Протвино | I6: 142281, Протвино, площадь Науки, 1 | J6: Понедельник-пятница: 9.00-16.30. Суббота и воскресенье: выходные дни. | K6: 8 (916) 730-92-98 | L6: aspirantura_ihep@ihep.ru | M6: =VLOOKUP(G6,справочник!$B$1:$C$94,2,0) -> МСК
A7: Негосударственная или частная организация | B7: 7617 | C7: «Научно-исследовательский «Центр развития энергетического права и современной правовой науки имени В.А. Мусина" | D7: 1207700260360 | E7: Научные учреждения | F7: Центральный ФО | G7: г.Москва | H7: Москва | I7: 123112, Москва, Пресненская набережная, 12 | J7: понедельник-пятница: 9:00-19:00, суббота и воскресенье: выходной | K7: +7 (495) 150-75-69 | L7: musinlc@musinlc.ru | M7: =VLOOKUP(G7,справочник!$B$1:$C$94,2,0) -> МСК
A8: Федеральное агенство по техническому регулированию и метрологии (РОССТАНДАРТ) | B8: 7614 | C8: «Научно-исследовательский центр прикладной метрологии - Ростест» | D8: 1027700066415 | E8: Научные учреждения | F8: Центральный ФО | G8: г.Москва | H8: Москва | I8: 117418, Москва, Нахимовский проспект, 31 | J8: понедельник - четверг: 9:00-17:00, пятница: 9:00-16:00, суббота и воскресенье: выходной | K8: 8 495 437 40 61 | L8: ElenaVR@rostest.ru | M8: =VLOOKUP(G8,справочник!$B$1:$C$94,2,0) -> МСК
A9: Правительство Российской Федерации | B9: 7579 | C9: «Научно-производственное предприятие «Исток» имени А.И. Шокина» | D9: 1135050007400 | E9: Акционерное общество | F9: Центральный ФО | G9: Московская область | H9: Фрязино | I9: 141190, Фрязино, Вокзальная, 2а | J9: Понедельник-пятница: 9:00-16:00 суббота и воскресенье: выходной | K9: 8(495)465-86-80 (доб. 20-45) | L9: aspirantura@istokmw.ru | M9: =VLOOKUP(G9,справочник!$B$1:$C$94,2,0) -> МСК
A10: Правительство Российской Федерации | B10: 4009 | C10: «Петербургский институт ядерной физики им. Б.П. Константинова Национального исследовательского центра «Курчатовский институт» | D10: 1034701242443 | E10: Научные учреждения | F10: Северо-Западный ФО | G10: Ленинградская область | H10: Гатчина | I10: 188300, Гатчина, мкр Орлова роща, 1 | J10: НИЦ "Курчатовский институт" - ПИЯФ: понедельник-пятница, 9:00-12:00, 14:00-17:00; суббота, воскресенье: выходной; филиал НИЦ "Курчатовский институт" - ПИЯФ - ИВС: понедельник-пятница, 10:00-15:00; суббота, воскресенье: выходной; филиал НИЦ "Курчатовский институт" - ПИЯФ - ИХС: понедельник-пятница, 10:00-15:00; суббота, воскресенье: выходной. | K10: НИЦ "Курчатовский институт" - ПИЯФ: 8(81371)46125; филиал НИЦ "Курчатовский институт" - ПИЯФ - ИВС: 8(812)3233345; филиал НИЦ "Курчатовский институт" - ПИЯФ - ИХС: 8(812)3288594. | L10: НИЦ "Курчатовский институт" - ПИЯФ: aspirantura@pnpi.nrcki.ru; филиал НИЦ "Курчатовский институт" - ПИЯФ - ИВС: krasnopeeva_el@pnpi.nrcki.ru; филиал НИЦ "Курчатовский институт" - ПИЯФ - ИХС: sinelshchikova_oy@pnpi.nrcki.ru. | M10: =VLOOKUP(G10,справочник!$B$1:$C$94,2,0) -> МСК
A11: Федеральное агентство водных ресурсов (Росводресурсы) | B11: 7546 | C11: «Российский научно-исследовательский институт комплексного использования и охраны водных ресурсов» | D11: 1156658087739 | E11: Государственные учреждения | F11: Южный ФО | G11: Ростовская область | H11: Ростов-на-Дону | I11: 344037, Ростов-на-Дону, Ченцова, здание 10а | J11: понедельник-пятница: 10:00-16:00 суббота и воскресенье: выходной | K11: +7 (863) 285-30-24 | L11: aspirant-rwec@mail.ru | M11: =VLOOKUP(G11,справочник!$B$1:$C$94,2,0) -> МСК
A12: Негосударственная или частная организация | B12: 7754 | C12: «Тихоокеанский институт предпринимательства, туризма и права» | D12: 1224100003115 | E12: Высшее образование | F12: Дальневосточный ФО | G12: Камчатский край | H12: Петропавловск-Камчатский | I12: 683003, Петропавловск-Камчатский, Ключевская, 11 | J12: понедельник-пятница: 9:00-18:00, суббота 9:00-15:00, воскресенье: выходной | K12: 84152-42-80-01 | L12: info@tiptp.ru | M12: =VLOOKUP(G12,справочник!$B$1:$C$94,2,0) -> МСК+9
A13: Негосударственная или частная организация | B13: 7323 | C13: «Уральский медицинский институт» | D13: 1207400041870 | E13: Высшее образование | F13: Уральский ФО | G13: Челябинская область | H13: Челябинск | I13: 454092, Челябинск, Курчатова, 9 | J13: понедельник-пятница 8:00-17:00, суббота и воскресенье: выходной | K13: +79011479700 | L13: info@umedvuz.ru | M13: =VLOOKUP(G13,справочник!$B$1:$C$94,2,0) -> МСК+2
... A132: Министерство науки и высшего образования Российской Федерации (Минобрнауки России) | B132: 2072 | C132: Всероссийский научно-исследовательский ветеринарный институт патологии, фармакологии и терапии | D132: 1023601576360 | E132: Научные учреждения | F132: Центральный ФО | G132: Воронежская область | H132: Воронеж | I132: 394087, Воронеж, Ломоносова, 114-Б | J132: понедельник-четверг:10:00-15:00, перерыв 12:00-13:00; пятница: 11:00-12:00; суббота и воскресенье: выходной | K132: 8(473)253-92-81 | L132: t.e.lobodina@mail.ru | M132: =VLOOKUP(G132,справочник!$B$1:$C$94,2,0) -> МСК
A133: Федеральное агентство по недропользованию (Роснедра) | B133: 7400 | C133: Всероссийский научно-исследовательский геологический нефтяной институт | D133: 1167746108672 | E133: Научные учреждения | F133: Центральный ФО | G133: г.Москва | J133: понедельник:10.00 -17.00 среда:10.00 - 17.00 четверг:10.00 - 17.00 суббота и воскресенье: выходной | K133: +7 (499) 781-68-63 | L133: aspirantura@vnigni.ru | M133: =VLOOKUP(G133,справочник!$B$1:$C$94,2,0) -> МСК
A134: Министерство сельского хозяйства Российской Федерации (Минсельхоз России) | B134: 2559 | C134: Всероссийский научно-исследовательский и технологический институт биологической промышленности | D134: 1035010214436 | E134: Научные учреждения | F134: Центральный ФО | G134: Московская область | H134: поселок Биокомбината | I134: 141142, поселок Биокомбината, х, 17 | J134: понедельник-четверг: 8:00-17:00 пятница:8:00-16:00 суббота и воскресенье: выходной | K134: +7 (496) 567-32-63 | L134: centrkomp_vnitibp@mail.ru | M134: =VLOOKUP(G134,справочник!$B$1:$C$94,2,0) -> МСК
A135: Негосударственная или частная организация | B135: 3157 | C135: Всероссийский научно-исследовательский институт авиационных материалов Национального исследовательского центра «Курчатовский институт» | D135: 1027739045399 | E135: Унитарные предприятия | F135: Центральный ФО | G135: г.Москва | H135: Москва | I135: 105005, Москва, Радио, 17 | J135: понедельник-четверг: 9:00-17:30 пятница: 9:00-16:30 обед: 13:00-14:00 суббота и воскресенье: выходной | K135: 8-499-263-86-62 | L135: priem@viam.ru | M135: =VLOOKUP(G135,справочник!$B$1:$C$94,2,0) -> МСК
A136: Министерство науки и высшего образования Российской Федерации (Минобрнауки России) | B136: 1880 | C136: Всероссийский научно-исследовательский институт агрохимии имени Д.Н. Прянишникова | D136: 1037713026560 | E136: Научные учреждения | F136: Центральный ФО | G136: г.Москва | H136: Москва | I136: 127434, Москва, улица Прянишникова, 31 а | J136: понедельник-четверг: 9:30-17:30 пятница: 9:30-16:00 | K136: +7 (499) 977-09-44 | L136: aspirantura@vniia-pr.ru, kpk@vniia-pr.ru | M136: =VLOOKUP(G136,справочник!$B$1:$C$94,2,0) -> МСК
A137: Министерство науки и высшего образования Российской Федерации (Минобрнауки России) | B137: 2943 | C137: Всероссийский научно-исследовательский институт защиты растений | D137: 1027809005124 | E137: Научные учреждения | F137: Северо-Западный ФО | G137: г.Санкт-Петербург | H137: Пушкин | I137: 196608, Пушкин, шоссе Подбельского, 3 | J137: понедельник-четверг: 10:00-15:00 пятница, суббота и воскресенье:выходной | K137: 8(812)4704384 | L137: graduate@vizr.spb.ru | M137: =VLOOKUP(G137,справочник!$B$1:$C$94,2,0) -> МСК
A138: Министерство науки и высшего образования Российской Федерации (Минобрнауки России) | B138: 2638 | C138: Всероссийский научно-исследовательский институт коневодства имени академика В.В. Калашникова | D138: 1036216005231 | E138: Научные учреждения | F138: Центральный ФО | G138: Рязанская область | H138: Дивово | I138: 391105, Дивово, Ученых, нет | J138: понедельник-четверг: 9:00-16:30, пятница: 9:00-14:00 | K138: (4912)24-02-65, доп. 115 | L138: vniik08@mail.ru | M138: =VLOOKUP(G138,справочник!$B$1:$C$94,2,0) -> МСК
A139: Министерство науки и высшего образования Российской Федерации (Минобрнауки России) | B139: 1864 | C139: Всероссийский научно-исследовательский институт лекарственных и ароматических растений | D139: 1027700388066 | E139: Научные учреждения | F139: Центральный ФО | G139: г.Москва | H139: Москва | I139: 117216, Москва, Грина, 7 | J139: понедельник-четверг: 10:00-17:00 пятница: 10:00-16:00 суббота и воскресенье: выходной | K139: 8(495)712-16-63 | L139: lanatomilova@yandex.ru | M139: =VLOOKUP(G139,справочник!$B$1:$C$94,2,0) -> МСК
A140: Федеральное агентство лесного хозяйства (Рослесхоз) | B140: 3432 | C140: Всероссийский научно-исследовательский институт лесоводства и механизации лесного хозяйства | D140: 1025004911315 | E140: Научные учреждения | F140: Центральный ФО | G140: Московская область | H140: Пушкино | I140: 141202, Пушкино, Институтская, 15 | J140: понедельник-четверг: 10:00-17:00 пятница: 10:00-16:00 суббота и воскресенье: выходной | K140: 8-495-993-30-54 | L140: nmo@vniilm.ru | M140: =VLOOKUP(G140,справочник!$B$1:$C$94,2,0) -> МСК
A141: Федеральное агенство по техническому регулированию и метрологии (РОССТАНДАРТ) | B141: 3451 | C141: Всероссийский научно-исследовательский институт метрологии им. Д.И. Менделеева | D141: 1027810219007 | E141: Научные учреждения | F141: Северо-Западный ФО | G141: г.Санкт-Петербург | H141: Санкт-петербург | I141: 190005, Санкт-петербург, Московский проспект, 19 | J141: понедельник-четверг: 9:00-17:00 пятница: 9:00-14.15 суббота и воскресенье: выходной | K141: 8(812)323-93-79 | L141: a.a.tinkova@vniim.ru | M141: =VLOOKUP(G141,справочник!$B$1:$C$94,2,0) -> МСК
A142: Министерство науки и высшего образования Российской Федерации (Минобрнауки России) | B142: 1805 | C142: Всероссийский научно-исследовательский институт молочной промышленности | D142: 1037739374672 | E142: Научные учреждения | F142: Центральный ФО | G142: г.Москва | H142: Москва | I142: 115093, Москва, Люсиновская, 35 | J142: понедельник-вторник: 10:00-16:00 среда-воскресенье: выходной | K142: - | L142: aspirantura@vnimi.org | M142: =VLOOKUP(G142,справочник!$B$1:$C$94,2,0) -> МСК
A143: Федеральное агенство по техническому регулированию и метрологии (РОССТАНДАРТ) | B143: 3429 | C143: Всероссийский научно-исследовательский институт оптико-физических измерений | D143: 1237700065470 | E143: Государственные учреждения | F143: Центральный ФО | G143: г.Москва | H143: Москва | I143: 119361, Москва, Озерная, 46 | J143: понедельник-четверг: 10:00-17:00, пятница: 10:00-16:00, суббота и воскресенье: выходной | K143: +74957812447 | L143: science@vniiofi.ru | M143: =VLOOKUP(G143,справочник!$B$1:$C$94,2,0) -> МСК
A144: Министерство науки и высшего образования Российской Федерации (Минобрнауки России) | B144: 2296 | C144: Всероссийский научно-исследовательский институт охотничьего хозяйства и звероводства имени профессора Б.М. Житкова | D144: 1024301308680 | E144: Научные учреждения | F144: Приволжский ФО | G144: Кировская область | H144: Киров | I144: 610020, Киров, Преображенская, 79 | J144: понедельник-четверг: 9:00-17:30, пятница: 9:00-16:00, суббота и воскресенье: выходной | K144: 8(8332) 64-66-61 | L144: aspirantura@vniioz-kirov.ru | M144: =VLOOKUP(G144,справочник!$B$1:$C$94,2,0) -> МСК
A145: Федеральное агентство по рыболовству (Росрыболовство) | B145: 3608 | C145: Всероссийский научно-исследовательский институт рыбного хозяйства и океанографии | D145: 1157746053431 | E145: Научные учреждения | F145: Центральный ФО | G145: г.Москва | H145: Москва | I145: 105187, Москва, Окружной проезд, 19 | J145: понедельник-четверг: 10:00-17:00 пятница: 10:00-16:00 суббота и воскресенье: выходной | K145: 84993690306 | L145: aspirant@vniro.ru | M145: =VLOOKUP(G145,справочник!$B$1:$C$94,2,0) -> МСК
... A346: Министерство науки и высшего образования Российской Федерации (Минобрнауки России) | B346: 2698 | C346: Институт органической химии им. Н.Д. Зелинского Российской академии наук | D346: 1027700304323 | E346: Научные учреждения | F346: Центральный ФО | G346: г.Москва | H346: МОСКВА | I346: 119991, МОСКВА, ПРОСПЕКТ ЛЕНИНСКИЙ, д 47 | J346: понедельник-четверг: 11:00-18:30 пятница: 11:00-16:30 суббота и воскресенье: выходной | K346: 8-499-137-71-91 | L346: vesela@ioc.ac.ru | M346: =VLOOKUP(G346,справочник!$B$1:$C$94,2,0) -> МСК
A347: Субъект Российской Федерации | B347: 7349 | C347: Институт повышения квалификации руководящих работников и специалистов | D347: 1035002452132 | E347: Образовательные учреждение дополнительного профессионального образования | F347: Центральный ФО | G347: Московская область | J347: Понедельник-пятница с 09:00 до 17:00 Суббота, воскресень выходной день | K347: 8-925-629-1105 | L347: i.voropaev@ipkmeteo.ru | M347: =VLOOKUP(G347,справочник!$B$1:$C$94,2,0) -> МСК
A348: Министерство науки и высшего образования Российской Федерации (Минобрнауки России) | B348: 2202 | C348: Институт прикладной астрономии Российской академии наук | D348: 1037828005852 | E348: Научные учреждения | F348: Северо-Западный ФО | G348: г.Санкт-Петербург | H348: Санкт-Петербург | I348: 191187, Санкт-Петербург, Кутузова набережная, 10 | J348: понедельник-пятница: 10:00-17:00, суббота и воскресенье: выходной | K348: 8 (812) 275 10 15 | L348: zmb@iaaras.ru | M348: =VLOOKUP(G348,справочник!$B$1:$C$94,2,0) -> МСК
A349: Министерство науки и высшего образования Российской Федерации (Минобрнауки России) | B349: 1854 | C349: Институт прикладной механики Российской академии наук | D349: 1037700153182 | E349: Научные учреждения | F349: Центральный ФО | G349: г.Москва | H349: Москва | I349: 125040, Москва, Ленинградский проспект, 7 | J349: понедельник-четверг: 12:00-16:00 пятница-воскресенье: выходной | K349: +7(906)726-06-88 | L349: aspirantura@iam.ras.ru | M349: =VLOOKUP(G349,справочник!$B$1:$C$94,2,0) -> МСК
A350: Министерство науки и высшего образования Российской Федерации (Минобрнауки России) | B350: 1964 | C350: Институт проблем безопасного развития атомной энергетики Российской академии наук | D350: 1027700196468 | E350: Научные учреждения | F350: Центральный ФО | G350: г.Москва | H350: Москва | I350: 115191, Москва, Тульская Б., 52 | J350: понедельник- четверг: 9:00-16:00 пятница : 9:00-15:00 суббота и воскресенье: выходной | K350: 8-495-955-23-10 | L350: pbl@ibrae.ac.ru | M350: =VLOOKUP(G350,справочник!$B$1:$C$94,2,0) -> МСК
A351: Министерство науки и высшего образования Российской Федерации (Минобрнауки России) | B351: 4032 | C351: Институт проблем искусственного интеллекта | D351: 1229300155182 | E351: Научные учреждения | F351: Южный ФО | G351: Донецкая Народная Республика | H351: Донецк | I351: 283048, Донецк, Артема, 118Б | J351: понедельник-пятница: 10:00-15:00 суббота и воскресенье: выходной | K351: +7(949) 439-76-82 | L351: aspirantura.ipai@yandex.ru | M351: =VLOOKUP(G351,справочник!$B$1:$C$94,2,0) -> МСК
A352: Министерство науки и высшего образования Российской Федерации (Минобрнауки России) | B352: 1788 | C352: Институт проблем комплексного освоения недр им. академика Н.В. Мельникова Российской академии наук | D352: 1037700121150 | E352: Научные учреждения | F352: Центральный ФО | G352: г.Москва | H352: Москва | I352: 111020, Москва, Крюковский туп., 4 | J352: понедельник-четверг: 12:00-17:00 пятница: 12:00-16:30 суббота и воскресенье: выходной | K352: +7(495) 360-49-04 | L352: aspirantyra_ipkon@mail.ru | M352: =VLOOKUP(G352,справочник!$B$1:$C$94,2,0) -> МСК
A353: Министерство науки и высшего образования Российской Федерации (Минобрнауки России) | B353: 1783 | C353: Институт проблем машиноведения Российской академии наук | D353: 1037800003560 | E353: Научные учреждения | F353: Северо-Западный ФО | G353: г.Санкт-Петербург | H353: Санкт-Петербург | I353: 199178, Санкт-Петербург, Васильевский остров. Большой проспект, 61 | J353: понедельник-четверг: 10:30-17:30 пятница: 10:30-16:30 суббота и воскресенье: выходной | K353: 8(812)321-47-72 | L353: aspirant@ipme.ru | M353: =VLOOKUP(G353,справочник!$B$1:$C$94,2,0) -> МСК
A354: Министерство науки и высшего образования Российской Федерации (Минобрнауки России) | B354: 1791 | C354: Институт проблем механики им. А.Ю. Ишлинского Российской академии наук | D354: 1037739426735 | E354: Научные учреждения | F354: Центральный ФО | G354: г.Москва | H354: Москва | I354: 119526, Москва, проспект Вернадского, 101 | J354: Понедельник - четверг 10:00 - 16:00, пятница 10:00 - 15:00, суббота и воскресенье: выходной. | K354: +7-495- 4343351 | L354: aspirantura@ipmnet.ru | M354: =VLOOKUP(G354,справочник!$B$1:$C$94,2,0) -> МСК
A355: Министерство науки и высшего образования Российской Федерации (Минобрнауки России) | B355: 2749 | C355: Институт проблем морских технологий им. академика М.Д. Агеева Дальневосточного отделения Российской академии наук | D355: 1022501279877 | E355: Научные учреждения | F355: Дальневосточный ФО | G355: Приморский край | H355: Владивосток | I355: 690091, Владивосток, Суханова, 5а | J355: понедельник-пятница: 9:00-15:00 суббота и воскресенье: выходной | K355: +7 (423) 243-24-16 | L355: aspirant@marine.febras.ru | M355: =VLOOKUP(G355,справочник!$B$1:$C$94,2,0) -> МСК+7
A356: Министерство науки и высшего образования Российской Федерации (Минобрнауки России) | B356: 2257 | C356: Институт проблем нефти и газа Российской академии наук | D356: 1037739238195 | E356: Научные учреждения | F356: Центральный ФО | G356: г.Москва | H356: Москва | I356: 119333, Москва, Губкина, 3 | J356: понедельник-вторник-четверг: 11:00-17:00 пятница: 11:00-16:00 суббота и воскресенье: выходной | K356: 84991357311 | L356: aspirant@ipng.ru | M356: =VLOOKUP(G356,справочник!$B$1:$C$94,2,0) -> МСК
A357: Министерство науки и высшего образования Российской Федерации (Минобрнауки России) | B357: 2331 | C357: Институт проблем передачи информации им. А.А. Харкевича Российской академии наук | D357: 1037700064940 | E357: Научные учреждения | F357: Центральный ФО | G357: г.Москва | H357: Москва | I357: 127051, Москва, Большой Каретный переулок, 19 | J357: Пример: понедельник-четверг: 9:00-17:30 пятница суббота и воскресенье: выходной | K357: 8-495-699-54-91 | L357: naumova@iitp.ru | M357: =VLOOKUP(G357,справочник!$B$1:$C$94,2,0) -> МСК
A358: Министерство науки и высшего образования Российской Федерации (Минобрнауки России) | B358: 1778 | C358: Институт проблем развития науки Российской академии наук | D358: 1057747667658 | E358: Научные учреждения | F358: Центральный ФО | G358: г.Москва | H358: Москва | I358: 117218, Москва, Нахимовский пр-т, 32 | J358: - | K358: 8(495)2490274 | L358: posta@issras.ru | M358: =VLOOKUP(G358,справочник!$B$1:$C$94,2,0) -> МСК
...

Sheet справочник
A1: Абакан | B1: Республика Хакасия | C1: МСК+4
A2: Анадырь | B2: Чукотский автономный округ | C2: МСК+9
A3: Архангельск | B3: Архангельская область | C3: МСК
A4: Астрахань | B4: Астраханская область | C4: МСК+1
A5: Барнаул | B5: Алтайский край | C5: МСК+4
A6: Белгород | B6: Белгородская область | C6: МСК
A7: Биробиджан | B7: Еврейская автономная область | C7: МСК+7
A8: Благовещенск | B8: Амурская область | C8: МСК+6
A9: Брянск | B9: Брянская область | C9: МСК
A10: Великий Новгород | B10: Новгородская область | C10: МСК
A11: Владивосток | B11: Приморский край | C11: МСК+7
A12: Владикавказ | B12: Республика Северная Осетия - Алания | C12: МСК
... A94: Херсон | B94: Херсонская область | C94: МСК

Sheet примеч
A1: Абакан | B1: Республика Хакасия | C1: UTC+7
A2: Анадырь | B2: Чукотский автономный округ | C2: UTC+12
A3: Архангельск | B3: Архангельская область | C3: UTC+3
A4: Астрахань | B4: Астраханская область | C4: UTC+4
A5: Барнаул | B5: Алтайский край | C5: UTC+7
A6: Белгород | B6: Белгородская область | C6: UTC+3
A7: Биробиджан | B7: Еврейская автономная область | C7: UTC+10
A8: Благовещенск | B8: Амурская область | C8: UTC+9
A9: Брянск | B9: Брянская область | C9: UTC+3
A10: Великий Новгород | B10: Новгородская область | C10: UTC+3
A11: Владивосток | B11: Приморский край | C11: UTC+10
A12: Владикавказ | B12: Республика Северная Осетия - Алания | C12: UTC+3
... A83: Ярославль | B83: Ярославская область | C83: UTC+3
